Workbook
Name _________AFC1: [1]INV!$A$25:$D$28
Name _________AFC3: [1]INV!$F$25:$I$28
Name _________AFC5: [1]INV!$K$25:$N$28
Name _________BGC1: [1]INV!$A$5:$D$8
Name _________BGC3: [1]INV!$F$5:$I$8
Name _________BGC5: [1]INV!$K$5:$N$8
Name _________CAC1: [1]INV!$A$19:$D$22
Name _________CAC3: [1]INV!$F$19:$I$22
Name _________CAC5: [1]INV!$K$19:$N$22
Name _________key2: [2]INST!#REF!
Name _________key2: [2]INST!#REF!
Name _________PJ50: #REF!
Name _________PJ50: #REF!
Name _________SBC1: [1]INV!$A$12:$D$15
Name _________SBC3: [1]INV!$F$12:$I$15
Name _________SBC5: [1]INV!$K$12:$N$15
Name ________AFC1: [1]INV!$A$25:$D$28
Name ________AFC3: [1]INV!$F$25:$I$28
Name ________AFC5: [1]INV!$K$25:$N$28
Name ________BGC1: [1]INV!$A$5:$D$8
Name ________BGC3: [1]INV!$F$5:$I$8
Name ________BGC5: [1]INV!$K$5:$N$8
Name ________CAC1: [1]INV!$A$19:$D$22
Name ________CAC3: [1]INV!$F$19:$I$22
Name ________CAC5: [1]INV!$K$19:$N$22
Name ________key2: [3]INST!#REF!
Name ________key2: [3]INST!#REF!
Name ________key3: #REF!
Name ________key3: #REF!
Name ________MA2: #REF!
Name ________MA2: #REF!
Name ________PJ50: #REF!
Name ________PJ50: #REF!
Name ________SBC1: [1]INV!$A$12:$D$15
Name ________SBC3: [1]INV!$F$12:$I$15
Name ________SBC5: [1]INV!$K$12:$N$15
Name _______AFC1: [1]INV!$A$25:$D$28
Name _______AFC3: [1]INV!$F$25:$I$28
Name _______AFC5: [1]INV!$K$25:$N$28
Name _______BGC1: [1]INV!$A$5:$D$8
Name _______BGC3: [1]INV!$F$5:$I$8
Name _______BGC5: [1]INV!$K$5:$N$8
Name _______CAC1: [1]INV!$A$19:$D$22
Name _______CAC3: [1]INV!$F$19:$I$22
Name _______CAC5: [1]INV!$K$19:$N$22
Name _______MA2: #REF!
Name _______MA2: #REF!
Name _______PJ50: #REF!
Name _______PJ50: #REF!
Name _______SBC1: [1]INV!$A$12:$D$15
Name _______SBC3: [1]INV!$F$12:$I$15
Name _______SBC5: [1]INV!$K$12:$N$15
Name ______AFC1: [1]INV!$A$25:$D$28
Name ______AFC3: [1]INV!$F$25:$I$28
Name ______AFC5: [1]INV!$K$25:$N$28
Name ______BGC1: [1]INV!$A$5:$D$8
Name ______BGC3: [1]INV!$F$5:$I$8
Name ______BGC5: [1]INV!$K$5:$N$8
Name ______CAC1: [1]INV!$A$19:$D$22
Name ______CAC3: [1]INV!$F$19:$I$22

Sheet PRESUPUESTO
C4: Código | E4: Versión
C5: FORMULARIO 1
C6: PROPUESTA ECONÓMICA
C7: [La entidad puede utilizar este formulario de presentación de propuesta económica de forma detallada, sin perjuicio que la entidad pueda modificarlo o establecer la presentación de la oferta económica con un formulario distinto al indicado.] [Los proponentes emplearán el formulario establecido por la entidad para determinar su propuesta económica conforme al Formulario 1 - Presupuesto Oficial publicado por la Entidad]
C9: Cuando el proceso de contratación es estructurado por precios unitarios, la Entidad debe aplicar las notas 1, 2 y 3 del presente formato y las casillas de "Descripción", "Porcentaje" de la Administración, Utilidad y total A.I.U. resaltadas en color amarillo.
C11: Nº | D11: ÍTEM DE PAGO | E11: ESPECIFICACIONES | G11: DESCRIPCIÓN | H11: UND. | I11: CANTIDAD | J11: VALOR UNITARIO | K11: VALOR TOTAL
E12: GENERAL | F12: PARTICULAR
D13: 003 | G13: DESAGUES E INSTALACIONES SANITARIAS
D14: 003.014 | G14: SUMINISTRO, TRANSPORTE E INSTALACION PUNTO DESAGUE PVC 3" APARATOS SANITARIOS Y DESAGUES (INCLUYE CODO, YEE Y ACCESORIOS) | H14: UND. | I14: 1 | J14: 158003 | K14: =+ROUND(J14*I14,0) -> 158003
D15: 003.015 | G15: SUMINISTRO, TRANSPORTE E INSTALACION PUNTO DESAGUE PVC 3" APARATOS SANITARIOS Y DESAGUES (INCLUYE CODO, YEE Y ACCESORIOS) | H15: UND. | I15: 1 | J15: 206188 | K15: =+ROUND(J15*I15,0) -> 206188
C16: Subtotal | K16: =SUM(K14:K15) -> 364191
D17: 006 | G17: MAMPOSTERIA
D18: 006.019 | G18: SUMINISTRO, TRANSPORTE E INSTALACIÓN A TODO COSTO DE MURO EN SUPERBOARD 8 MM PINTADO Y TERMINADO (DOS CARAS). INCLUYE PERFILERÍA Y TODO LO NECESARIO PARA SU CORRECTA INSTALACIÓN | H18: M2 | I18: 135.19 | J18: 201149 | K18: =+ROUND(J18*I18,0) -> 27193333
C19: Subtotal | K19: =SUM(K18) -> 27193333
D20: 007 | G20: INSTALACIONES HIDRAULICAS
D21: 007.017 | G21: SUMINISTRO, TRANSPORTE E INSTALACION PUNTO AGUA FRIA 1/2" PVC -P ( INCLUYE ACCESORIOS DE INSTALACIÓN ) | H21: UND | I21: 1 | J21: 96040 | K21: =+ROUND(J21*I21,0) -> 96040
D22: 007.021 | G22: SUMINISTRO, TRANSPORTE E INSTALACION PUNTO AGUA CALIENTE 1/2" CPVC-P ( INCLUYE ACCESORIOS DE INSTALACIÓN ) | H22: UND | I22: 1 | J22: 182492 | K22: =+ROUND(J22*I22,0) -> 182492
C23: Subtotal | K23: =SUM(K21:K22) -> 278532
D24: 08B | G24: INSTALACIONES HIDRAULICAS
G25: INSTALACIONES ELECTRICAS
D26: 08B.844 | G26: SUMINISTRO E INSTALACIÓN BREAKER TOTALIZADOR 3X40A | H26: UND | I26: 3 | J26: 590278 | K26: =+ROUND(J26*I26,0) -> 1770834
D27: 08B.845 | G27: SUMINISTRO E INSTALACIÓN DE ACOMETIDA A TR EN CABLE DE COBRE HFFRLS 3#8(F)+1#8(N)+1#8(T), POR BANDEJA EXISTENTE | H27: ML | I27: 150 | J27: 77863 | K27: =+ROUND(J27*I27,0) -> 11679450
D28: 08B.846 | G28: SUMINISTRO E INSTALACIÓN TABLERO TRIFÁSICO DE 24 CTOS. CON ESPACIO PARA TOTALIZADOR (TN) | H28: UND | I28: 1 | J28: 938955 | K28: =+ROUND(J28*I28,0) -> 938955
D29: 08B.847 | G29: SUMINISTRO E INSTALACIÓN BREAKER ENCHUFABLE 1X20 A | H29: UND | I29: 64 | J29: 75923 | K29: =+ROUND(J29*I29,0) -> 4859072
D30: 08B.848 | G30: SUMINISTRO E INSTALACIÓN BREAKER ENCHUFABLE 2X20A | H30: UND | I30: 3 | J30: 160412 | K30: =+ROUND(J30*I30,0) -> 481236
D31: 08B.849 | G31: SUMINISTRO E INSTALACIÓN SALIDA ALUMBRADO CON TUBERÍA PVC SCH40 Y CABLE #12 HFFRLS | H31: UND | I31: 238 | J31: 177181 | K31: =+ROUND(J31*I31,0) -> 42169078
D32: 08B.850 | G32: SUMINISTRO E INSTALACIÓN SALIDA CON SENSOR DE MOVIMIENTO DE TECHO PARA ALUMBRADO CON TUBERÍA SCH40 Y CABLE #12 HFFRLS | H32: UND | I32: 5 | J32: 251167 | K32: =+ROUND(J32*I32,0) -> 1255835
D33: 08B.851 | G33: SUMINISTRO E INSTALACIÓN SALIDA INTERRUPTOR SENCILLO CON TUBERÍA PVC SCH40 Y CABLE #12 HFFRLS | H33: UND | I33: 26 | J33: 182809 | K33: =+ROUND(J33*I33,0) -> 4753034
D34: 08B.852 | G34: SUMINISTRO E INSTALACIÓN SALIDA INTERRUPTOR SENCILLO CON CABLE #12 LIBRE DE HALÓGENOS Y TUBERÍA PVC 1/2" | H34: UND | I34: 13 | J34: 205854 | K34: =+ROUND(J34*I34,0) -> 2676102
D35: 08B.853 | G35: SUMINISTRO E INSTALACIÓN SALIDA INTERRUPTOR DOBLE CON TUBERÍA PVC SCH40 Y CABLE #12 HFFRLS | H35: UND | I35: 7 | J35: 207797 | K35: =+ROUND(J35*I35,0) -> 1454579
D36: 08B.854 | G36: SUMINISTRO E INSTALACIÓN SALIDA INTERRUPTOR DOBLE CON CABLE #12 LIBRE DE HALÓGENOS Y TUBERÍA PVC 1/2" | H36: UND | I36: 3 | J36: 227671 | K36: =+ROUND(J36*I36,0) -> 683013
D37: 08B.855 | G37: SUMINISTRO E INSTALACIÓN SALIDA INTERRUPTOR TRIPLE CON TUBERÍA PVC SCH40 Y CABLE #12 HFFRLS | H37: UND | I37: 2 | J37: 234126 | K37: =+ROUND(J37*I37,0) -> 468252
... D61: 08B.880 | G61: SUMINISTRO E INSTALACIÓN TUBERÍA PVC SCH40 2" | H61: ML | I61: 59 | J61: 24598 | K61: =+ROUND(J61*I61,0) -> 1451282
G62: INSTALACIONES VOZ-DATOS
D63: 08B.881 | G63: SUMINISTRO E INSTALACIÓN CABLE UTP CAT. 6A 4P | H63: ML | I63: 9760 | J63: 11124 | K63: =+ROUND(J63*I63,0) -> 108570240
D64: 08B.882 | G64: SUMINISTRO E INSTALACIÓN TOMA RJ45 DOBLE CAT. 6A | H64: UND | I64: 156 | J64: 148727 | K64: =+ROUND(J64*I64,0) -> 23201412
D65: 08B.883 | G65: SUMINISTRO E INSTALACIÓN TOMA RJ45 SENCILLO CAT. 6A | H65: UND | I65: 10 | J65: 89217 | K65: =+ROUND(J65*I65,0) -> 892170
D66: 08B.884 | G66: SUMINISTRO E INSTALACIÓN HERRAJE ANGULADO 48 PTOS | H66: UND | I66: 6 | J66: 621577 | K66: =+ROUND(J66*I66,0) -> 3729462
D67: 08B.885 | G67: SUMINISTRO E INSTALACIÓN HERRAJE ANGULADO 24 PTOS | H67: UND | I67: 2 | J67: 621577 | K67: =+ROUND(J67*I67,0) -> 1243154
D68: 08B.886 | G68: SUMINISTRO E INSTALACIÓN JACK RJ45 CAT. 6A (EN RACK) | H68: UND | I68: 322 | J68: 61992 | K68: =+ROUND(J68*I68,0) -> 19961424
...

Sheet PROPUESTA ECONOMICA(Propone)
C4: Código | E4: Versión
C5: FORMULARIO 1
C6: PROPUESTA ECONÓMICA
C7: [La entidad puede utilizar este formulario de presentación de propuesta económica de forma detallada, sin perjuicio que la entidad pueda modificarlo o establecer la presentación de la oferta económica con un formulario distinto al indicado.] [Los proponentes emplearán el formulario establecido por la entidad para determinar su propuesta económica conforme al Formulario 1 - Presupuesto Oficial publicado por la Entidad]
C9: Cuando el proceso de contratación es estructurado por precios unitarios, la Entidad debe aplicar las notas 1, 2 y 3 del presente formato y las casillas de "Descripción", "Porcentaje" de la Administración, Utilidad y total A.I.U. resaltadas en color amarillo.
C11: Nº | D11: ÍTEM DE PAGO | E11: ESPECIFICACIONES | G11: DESCRIPCIÓN | H11: UND. | I11: CANTIDAD | J11: VALOR UNITARIO | K11: VALOR TOTAL
E12: GENERAL | F12: PARTICULAR
D13: 003 | G13: DESAGUES E INSTALACIONES SANITARIAS
D14: 003.014 | G14: SUMINISTRO, TRANSPORTE E INSTALACION PUNTO DESAGUE PVC 3" APARATOS SANITARIOS Y DESAGUES (INCLUYE CODO, YEE Y ACCESORIOS) | H14: UND. | I14: 1 | J14: =ROUND(PRESUPUESTO!J14*0.886,0) -> 139991 | K14: =+ROUND(J14*I14,0) -> 139991
D15: 003.015 | G15: SUMINISTRO, TRANSPORTE E INSTALACION PUNTO DESAGUE PVC 3" APARATOS SANITARIOS Y DESAGUES (INCLUYE CODO, YEE Y ACCESORIOS) | H15: UND. | I15: 1 | J15: =ROUND(PRESUPUESTO!J15*0.886,0) -> 182683 | K15: =+ROUND(J15*I15,0) -> 182683
C16: Subtotal | K16: =SUM(K14:K15) -> 322674
D17: 006 | G17: MAMPOSTERIA
D18: 006.019 | G18: SUMINISTRO, TRANSPORTE E INSTALACIÓN A TODO COSTO DE MURO EN SUPERBOARD 8 MM PINTADO Y TERMINADO (DOS CARAS). INCLUYE PERFILERÍA Y TODO LO NECESARIO PARA SU CORRECTA INSTALACIÓN | H18: M2 | I18: 135.19 | J18: =ROUND(PRESUPUESTO!J18*0.886,0) -> 178218 | K18: =+ROUND(J18*I18,0) -> 24093291
C19: Subtotal | K19: =SUM(K18) -> 24093291
D20: 007 | G20: INSTALACIONES HIDRAULICAS
D21: 007.017 | G21: SUMINISTRO, TRANSPORTE E INSTALACION PUNTO AGUA FRIA 1/2" PVC -P ( INCLUYE ACCESORIOS DE INSTALACIÓN ) | H21: UND | I21: 1 | J21: =ROUND(PRESUPUESTO!J21*0.886,0) -> 85091 | K21: =+ROUND(J21*I21,0) -> 85091
D22: 007.021 | G22: SUMINISTRO, TRANSPORTE E INSTALACION PUNTO AGUA CALIENTE 1/2" CPVC-P ( INCLUYE ACCESORIOS DE INSTALACIÓN ) | H22: UND | I22: 1 | J22: =ROUND(PRESUPUESTO!J22*0.886,0) -> 161688 | K22: =+ROUND(J22*I22,0) -> 161688
C23: Subtotal | K23: =SUM(K21:K22) -> 246779
D24: 08B | G24: INSTALACIONES HIDRAULICAS
G25: INSTALACIONES ELECTRICAS | J25: =ROUND(PRESUPUESTO!J25*0.886,0) -> 0
D26: 08B.844 | G26: SUMINISTRO E INSTALACIÓN BREAKER TOTALIZADOR 3X40A | H26: UND | I26: 3 | J26: =ROUND(PRESUPUESTO!J26*0.886,0) -> 522986 | K26: =+ROUND(J26*I26,0) -> 1568958
D27: 08B.845 | G27: SUMINISTRO E INSTALACIÓN DE ACOMETIDA A TR EN CABLE DE COBRE HFFRLS 3#8(F)+1#8(N)+1#8(T), POR BANDEJA EXISTENTE | H27: ML | I27: 150 | J27: =ROUND(PRESUPUESTO!J27*0.886,0) -> 68987 | K27: =+ROUND(J27*I27,0) -> 10348050
D28: 08B.846 | G28: SUMINISTRO E INSTALACIÓN TABLERO TRIFÁSICO DE 24 CTOS. CON ESPACIO PARA TOTALIZADOR (TN) | H28: UND | I28: 1 | J28: =ROUND(PRESUPUESTO!J28*0.886,0) -> 831914 | K28: =+ROUND(J28*I28,0) -> 831914
D29: 08B.847 | G29: SUMINISTRO E INSTALACIÓN BREAKER ENCHUFABLE 1X20 A | H29: UND | I29: 64 | J29: =ROUND(PRESUPUESTO!J29*0.886,0) -> 67268 | K29: =+ROUND(J29*I29,0) -> 4305152
D30: 08B.848 | G30: SUMINISTRO E INSTALACIÓN BREAKER ENCHUFABLE 2X20A | H30: UND | I30: 3 | J30: =ROUND(PRESUPUESTO!J30*0.886,0) -> 142125 | K30: =+ROUND(J30*I30,0) -> 426375
D31: 08B.849 | G31: SUMINISTRO E INSTALACIÓN SALIDA ALUMBRADO CON TUBERÍA PVC SCH40 Y CABLE #12 HFFRLS | H31: UND | I31: 238 | J31: =ROUND(PRESUPUESTO!J31*0.886,0) -> 156982 | K31: =+ROUND(J31*I31,0) -> 37361716
D32: 08B.850 | G32: SUMINISTRO E INSTALACIÓN SALIDA CON SENSOR DE MOVIMIENTO DE TECHO PARA ALUMBRADO CON TUBERÍA SCH40 Y CABLE #12 HFFRLS | H32: UND | I32: 5 | J32: =ROUND(PRESUPUESTO!J32*0.886,0) -> 222534 | K32: =+ROUND(J32*I32,0) -> 1112670
D33: 08B.851 | G33: SUMINISTRO E INSTALACIÓN SALIDA INTERRUPTOR SENCILLO CON TUBERÍA PVC SCH40 Y CABLE #12 HFFRLS | H33: UND | I33: 26 | J33: =ROUND(PRESUPUESTO!J33*0.886,0) -> 161969 | K33: =+ROUND(J33*I33,0) -> 4211194
D34: 08B.852 | G34: SUMINISTRO E INSTALACIÓN SALIDA INTERRUPTOR SENCILLO CON CABLE #12 LIBRE DE HALÓGENOS Y TUBERÍA PVC 1/2" | H34: UND | I34: 13 | J34: =ROUND(PRESUPUESTO!J34*0.886,0) -> 182387 | K34: =+ROUND(J34*I34,0) -> 2371031
D35: 08B.853 | G35: SUMINISTRO E INSTALACIÓN SALIDA INTERRUPTOR DOBLE CON TUBERÍA PVC SCH40 Y CABLE #12 HFFRLS | H35: UND | I35: 7 | J35: =ROUND(PRESUPUESTO!J35*0.886,0) -> 184108 | K35: =+ROUND(J35*I35,0) -> 1288756
D36: 08B.854 | G36: SUMINISTRO E INSTALACIÓN SALIDA INTERRUPTOR DOBLE CON CABLE #12 LIBRE DE HALÓGENOS Y TUBERÍA PVC 1/2" | H36: UND | I36: 3 | J36: =ROUND(PRESUPUESTO!J36*0.886,0) -> 201717 | K36: =+ROUND(J36*I36,0) -> 605151
D37: 08B.855 | G37: SUMINISTRO E INSTALACIÓN SALIDA INTERRUPTOR TRIPLE CON TUBERÍA PVC SCH40 Y CABLE #12 HFFRLS | H37: UND | I37: 2 | J37: =ROUND(PRESUPUESTO!J37*0.886,0) -> 207436 | K37: =+ROUND(J37*I37,0) -> 414872
... D61: 08B.880 | G61: SUMINISTRO E INSTALACIÓN TUBERÍA PVC SCH40 2" | H61: ML | I61: 59 | J61: =ROUND(PRESUPUESTO!J61*0.886,0) -> 21794 | K61: =+ROUND(J61*I61,0) -> 1285846
G62: INSTALACIONES VOZ-DATOS | J62: =ROUND(PRESUPUESTO!J62*0.886,0) -> 0
D63: 08B.881 | G63: SUMINISTRO E INSTALACIÓN CABLE UTP CAT. 6A 4P | H63: ML | I63: 9760 | J63: =ROUND(PRESUPUESTO!J63*0.886,0) -> 9856 | K63: =+ROUND(J63*I63,0) -> 96194560
D64: 08B.882 | G64: SUMINISTRO E INSTALACIÓN TOMA RJ45 DOBLE CAT. 6A | H64: UND | I64: 156 | J64: =ROUND(PRESUPUESTO!J64*0.886,0) -> 131772 | K64: =+ROUND(J64*I64,0) -> 20556432
D65: 08B.883 | G65: SUMINISTRO E INSTALACIÓN TOMA RJ45 SENCILLO CAT. 6A | H65: UND | I65: 10 | J65: =ROUND(PRESUPUESTO!J65*0.886,0) -> 79046 | K65: =+ROUND(J65*I65,0) -> 790460
D66: 08B.884 | G66: SUMINISTRO E INSTALACIÓN HERRAJE ANGULADO 48 PTOS | H66: UND | I66: 6 | J66: =ROUND(PRESUPUESTO!J66*0.886,0) -> 550717 | K66: =+ROUND(J66*I66,0) -> 3304302
D67: 08B.885 | G67: SUMINISTRO E INSTALACIÓN HERRAJE ANGULADO 24 PTOS | H67: UND | I67: 2 | J67: =ROUND(PRESUPUESTO!J67*0.886,0) -> 550717 | K67: =+ROUND(J67*I67,0) -> 1101434
D68: 08B.886 | G68: SUMINISTRO E INSTALACIÓN JACK RJ45 CAT. 6A (EN RACK) | H68: UND | I68: 322 | J68: =ROUND(PRESUPUESTO!J68*0.886,0) -> 54925 | K68: =+ROUND(J68*I68,0) -> 17685850
...
